[2024-04-22T20:49:01.870+0000] {local_task_job_runner.py:120} INFO - ::group::Pre task execution logs
[2024-04-22T20:49:01.886+0000] {taskinstance.py:2073} INFO - Dependencies all met for dep_context=non-requeueable deps ti=<TaskInstance: amazon_daily_ingest.insert_single manual__2024-04-22T20:48:40.506330+00:00 [queued]>
[2024-04-22T20:49:01.891+0000] {taskinstance.py:2073} INFO - Dependencies all met for dep_context=requeueable deps ti=<TaskInstance: amazon_daily_ingest.insert_single manual__2024-04-22T20:48:40.506330+00:00 [queued]>
[2024-04-22T20:49:01.892+0000] {taskinstance.py:2303} INFO - Starting attempt 1 of 1
[2024-04-22T20:49:01.900+0000] {taskinstance.py:2327} INFO - Executing <Task(SnowflakeOperator): insert_single> on 2024-04-22 20:48:40.506330+00:00
[2024-04-22T20:49:01.905+0000] {warnings.py:110} WARNING - /home/***/.local/lib/python3.12/site-packages/***/task/task_runner/standard_task_runner.py:61: DeprecationWarning: This process (pid=1349) is multi-threaded, use of fork() may lead to deadlocks in the child.
  pid = os.fork()

[2024-04-22T20:49:01.906+0000] {standard_task_runner.py:90} INFO - Running: ['***', 'tasks', 'run', 'amazon_daily_ingest', 'insert_single', 'manual__2024-04-22T20:48:40.506330+00:00', '--job-id', '40', '--raw', '--subdir', 'DAGS_FOLDER/amazon/dag.py', '--cfg-path', '/tmp/tmpr23ngbyp']
[2024-04-22T20:49:01.907+0000] {standard_task_runner.py:63} INFO - Started process 1358 to run task
[2024-04-22T20:49:01.907+0000] {standard_task_runner.py:91} INFO - Job 40: Subtask insert_single
[2024-04-22T20:49:01.955+0000] {task_command.py:426} INFO - Running <TaskInstance: amazon_daily_ingest.insert_single manual__2024-04-22T20:48:40.506330+00:00 [running]> on host 21d660d07eb5
[2024-04-22T20:49:02.041+0000] {taskinstance.py:2644} INFO - Exporting env vars: AIRFLOW_CTX_DAG_OWNER='***' AIRFLOW_CTX_DAG_ID='amazon_daily_ingest' AIRFLOW_CTX_TASK_ID='insert_single' AIRFLOW_CTX_EXECUTION_DATE='2024-04-22T20:48:40.506330+00:00' AIRFLOW_CTX_TRY_NUMBER='1' AIRFLOW_CTX_DAG_RUN_ID='manual__2024-04-22T20:48:40.506330+00:00'
[2024-04-22T20:49:02.042+0000] {taskinstance.py:430} INFO - ::endgroup::
[2024-04-22T20:49:02.043+0000] {sql.py:276} INFO - Executing: insert into AMAZON.RAW.FCT_DAILY_REVIEWS
select * , 'manual__2024-04-22T20:48:40.506330+00:00'
from AMAZON.RAW.duplicate_holder;
[2024-04-22T20:49:02.057+0000] {base.py:84} INFO - Using connection ID 'snowflake_trial' for task execution.
[2024-04-22T20:49:02.064+0000] {base.py:84} INFO - Using connection ID 'snowflake_trial' for task execution.
[2024-04-22T20:49:02.065+0000] {connection.py:386} INFO - Snowflake Connector for Python Version: 3.7.1, Python Version: 3.12.2, Platform: Linux-6.6.16-linuxkit-aarch64-with-glibc2.36
[2024-04-22T20:49:02.066+0000] {connection.py:1211} INFO - This connection is in OCSP Fail Open Mode. TLS Certificates would be checked for validity and revocation status. Any other Certificate Revocation related exceptions or OCSP Responder failures would be disregarded in favor of connectivity.
[2024-04-22T20:49:02.291+0000] {cursor.py:1032} INFO - query: [ALTER SESSION SET autocommit=False]
[2024-04-22T20:49:02.341+0000] {cursor.py:1045} INFO - query execution done
[2024-04-22T20:49:02.342+0000] {cursor.py:1205} INFO - Number of results in first chunk: 1
[2024-04-22T20:49:02.342+0000] {sql.py:457} INFO - Running statement: insert into AMAZON.RAW.FCT_DAILY_REVIEWS
select * , 'manual__2024-04-22T20:48:40.506330+00:00'
from AMAZON.RAW.duplicate_holder;, parameters: None
[2024-04-22T20:49:02.342+0000] {cursor.py:1032} INFO - query: [insert into AMAZON.RAW.FCT_DAILY_REVIEWS select * , 'manual__2024-04-22T20:48:40...]
[2024-04-22T20:49:02.395+0000] {cursor.py:1045} INFO - query execution done
[2024-04-22T20:49:02.441+0000] {connection.py:734} INFO - closed
[2024-04-22T20:49:02.465+0000] {connection.py:740} INFO - No async queries seem to be running, deleting session
[2024-04-22T20:49:02.518+0000] {taskinstance.py:441} INFO - ::group::Post task execution logs
[2024-04-22T20:49:02.522+0000] {taskinstance.py:2890} ERROR - Task failed with exception
Traceback (most recent call last):
  File "/home/airflow/.local/lib/python3.12/site-packages/airflow/models/taskinstance.py", line 465, in _execute_task
    result = _execute_callable(context=context, **execute_callable_kwargs)
             ^^^^^^^^^^^^^^^^^^^^^^^^^^^^^^^^^^^^^^^^^^^^^^^^^^^^^^^^^^^^^
  File "/home/airflow/.local/lib/python3.12/site-packages/airflow/models/taskinstance.py", line 432, in _execute_callable
    return execute_callable(context=context, **execute_callable_kwargs)
           ^^^^^^^^^^^^^^^^^^^^^^^^^^^^^^^^^^^^^^^^^^^^^^^^^^^^^^^^^^^^
  File "/home/airflow/.local/lib/python3.12/site-packages/airflow/models/baseoperator.py", line 400, in wrapper
    return func(self, *args, **kwargs)
           ^^^^^^^^^^^^^^^^^^^^^^^^^^^
  File "/home/airflow/.local/lib/python3.12/site-packages/airflow/providers/common/sql/operators/sql.py", line 282, in execute
    output = hook.run(
             ^^^^^^^^^
  File "/home/airflow/.local/lib/python3.12/site-packages/airflow/providers/snowflake/hooks/snowflake.py", line 390, in run
    self._run_command(cur, sql_statement, parameters)  # type: ignore[attr-defined]
    ^^^^^^^^^^^^^^^^^^^^^^^^^^^^^^^^^^^^^^^^^^^^^^^^^
  File "/home/airflow/.local/lib/python3.12/site-packages/airflow/providers/common/sql/hooks/sql.py", line 462, in _run_command
    cur.execute(sql_statement)
  File "/home/airflow/.local/lib/python3.12/site-packages/snowflake/connector/cursor.py", line 1136, in execute
    Error.errorhandler_wrapper(self.connection, self, error_class, errvalue)
  File "/home/airflow/.local/lib/python3.12/site-packages/snowflake/connector/errors.py", line 290, in errorhandler_wrapper
    handed_over = Error.hand_to_other_handler(
                  ^^^^^^^^^^^^^^^^^^^^^^^^^^^^
  File "/home/airflow/.local/lib/python3.12/site-packages/snowflake/connector/errors.py", line 345, in hand_to_other_handler
    cursor.errorhandler(connection, cursor, error_class, error_value)
  File "/home/airflow/.local/lib/python3.12/site-packages/snowflake/connector/errors.py", line 221, in default_errorhandler
    raise error_class(
snowflake.connector.errors.ProgrammingError: 002020 (21S01): 01b3d8c1-0000-df07-0001-980e00014086: SQL compilation error:
Insert value list does not match column list expecting 8 but got 5
[2024-04-22T20:49:02.586+0000] {taskinstance.py:1205} INFO - Marking task as FAILED. dag_id=amazon_daily_ingest, task_id=insert_single, execution_date=20240422T204840, start_date=20240422T204901, end_date=20240422T204902
[2024-04-22T20:49:02.610+0000] {standard_task_runner.py:110} ERROR - Failed to execute job 40 for task insert_single (002020 (21S01): 01b3d8c1-0000-df07-0001-980e00014086: SQL compilation error:
Insert value list does not match column list expecting 8 but got 5; 1358)
[2024-04-22T20:49:02.619+0000] {local_task_job_runner.py:240} INFO - Task exited with return code 1
[2024-04-22T20:49:02.650+0000] {taskinstance.py:3482} INFO - 0 downstream tasks scheduled from follow-on schedule check
[2024-04-22T20:49:02.654+0000] {local_task_job_runner.py:222} INFO - ::endgroup::
