[2024-04-22T15:01:31.179+0000] {local_task_job_runner.py:120} INFO - ::group::Pre task execution logs
[2024-04-22T15:01:31.189+0000] {taskinstance.py:2073} INFO - Dependencies all met for dep_context=non-requeueable deps ti=<TaskInstance: amazon_test.snowflake_op_sql_str scheduled__2024-03-01T00:00:00+00:00 [queued]>
[2024-04-22T15:01:31.192+0000] {taskinstance.py:2073} INFO - Dependencies all met for dep_context=requeueable deps ti=<TaskInstance: amazon_test.snowflake_op_sql_str scheduled__2024-03-01T00:00:00+00:00 [queued]>
[2024-04-22T15:01:31.192+0000] {taskinstance.py:2303} INFO - Starting attempt 3 of 3
[2024-04-22T15:01:31.196+0000] {taskinstance.py:2327} INFO - Executing <Task(SnowflakeOperator): snowflake_op_sql_str> on 2024-03-01 00:00:00+00:00
[2024-04-22T15:01:31.200+0000] {warnings.py:110} WARNING - /home/***/.local/lib/python3.12/site-packages/***/task/task_runner/standard_task_runner.py:61: DeprecationWarning: This process (pid=376) is multi-threaded, use of fork() may lead to deadlocks in the child.
  pid = os.fork()

[2024-04-22T15:01:31.201+0000] {standard_task_runner.py:90} INFO - Running: ['***', 'tasks', 'run', 'amazon_test', 'snowflake_op_sql_str', 'scheduled__2024-03-01T00:00:00+00:00', '--job-id', '5', '--raw', '--subdir', 'DAGS_FOLDER/amazon/dag.py', '--cfg-path', '/tmp/tmpkeyvw7wx']
[2024-04-22T15:01:31.202+0000] {standard_task_runner.py:63} INFO - Started process 378 to run task
[2024-04-22T15:01:31.202+0000] {standard_task_runner.py:91} INFO - Job 5: Subtask snowflake_op_sql_str
[2024-04-22T15:01:31.238+0000] {task_command.py:426} INFO - Running <TaskInstance: amazon_test.snowflake_op_sql_str scheduled__2024-03-01T00:00:00+00:00 [running]> on host 21d660d07eb5
[2024-04-22T15:01:31.275+0000] {taskinstance.py:2644} INFO - Exporting env vars: AIRFLOW_CTX_DAG_OWNER='***' AIRFLOW_CTX_DAG_ID='amazon_test' AIRFLOW_CTX_TASK_ID='snowflake_op_sql_str' AIRFLOW_CTX_EXECUTION_DATE='2024-03-01T00:00:00+00:00' AIRFLOW_CTX_TRY_NUMBER='3' AIRFLOW_CTX_DAG_RUN_ID='scheduled__2024-03-01T00:00:00+00:00'
[2024-04-22T15:01:31.276+0000] {taskinstance.py:430} INFO - ::endgroup::
[2024-04-22T15:01:31.276+0000] {sql.py:276} INFO - Executing: CREATE OR REPLACE TRANSIENT TABLE sample_table (name VARCHAR(250), id INT);
[2024-04-22T15:01:31.280+0000] {base.py:84} INFO - Using connection ID 'snowflake_trial' for task execution.
[2024-04-22T15:01:31.284+0000] {base.py:84} INFO - Using connection ID 'snowflake_trial' for task execution.
[2024-04-22T15:01:31.284+0000] {connection.py:386} INFO - Snowflake Connector for Python Version: 3.7.1, Python Version: 3.12.2, Platform: Linux-6.6.16-linuxkit-aarch64-with-glibc2.36
[2024-04-22T15:01:31.285+0000] {connection.py:1211} INFO - This connection is in OCSP Fail Open Mode. TLS Certificates would be checked for validity and revocation status. Any other Certificate Revocation related exceptions or OCSP Responder failures would be disregarded in favor of connectivity.
[2024-04-22T15:01:31.899+0000] {connection.py:547} WARNING - Certificate did not match expected hostname: jg26601.eu-west-2.aws.snowflakecomputing.com.snowflakecomputing.com. Certificate: {'subject': ((('commonName', '*.prod3.us-west-2.snowflakecomputing.com'),),), 'subjectAltName': [('DNS', '*.prod3.us-west-2.snowflakecomputing.com'), ('DNS', '*.us-west-2.snowflakecomputing.com'), ('DNS', '*.global.snowflakecomputing.com'), ('DNS', '*.snowflakecomputing.com'), ('DNS', '*.prod3.us-west-2.aws.snowflakecomputing.com')]}
[2024-04-22T15:01:31.900+0000] {connectionpool.py:824} WARNING - Retrying (Retry(total=0, connect=None, read=None, redirect=None, status=None)) after connection broken by 'SSLError(CertificateError("hostname 'jg26601.eu-west-2.aws.snowflakecomputing.com.snowflakecomputing.com' doesn't match either of '*.prod3.us-west-2.snowflakecomputing.com', '*.us-west-2.snowflakecomputing.com', '*.global.snowflakecomputing.com', '*.snowflakecomputing.com', '*.prod3.us-west-2.aws.snowflakecomputing.com'"))': /session/v1/login-request?request_id=e1048fbe-72c8-43ac-a6ee-add1f9b708ec&databaseName=AMAZON&schemaName=RAW&warehouse=COMPUTE_WH&roleName=&request_guid=91004b98-0563-43b0-9849-14bf4553f651
[2024-04-22T15:01:32.396+0000] {connection.py:547} WARNING - Certificate did not match expected hostname: jg26601.eu-west-2.aws.snowflakecomputing.com.snowflakecomputing.com. Certificate: {'subject': ((('commonName', '*.prod3.us-west-2.snowflakecomputing.com'),),), 'subjectAltName': [('DNS', '*.prod3.us-west-2.snowflakecomputing.com'), ('DNS', '*.us-west-2.snowflakecomputing.com'), ('DNS', '*.global.snowflakecomputing.com'), ('DNS', '*.snowflakecomputing.com'), ('DNS', '*.prod3.us-west-2.aws.snowflakecomputing.com')]}
[2024-04-22T15:01:32.404+0000] {network.py:1029} ERROR - Failed to get the response. Hanging? method: post, url: https://jg26601.eu-west-2.aws.snowflakecomputing.com.snowflakecomputing.com:443/session/v1/login-request?request_id=e1048fbe-72c8-43ac-a6ee-add1f9b708ec&databaseName=AMAZON&schemaName=RAW&warehouse=COMPUTE_WH&roleName=&request_guid=91004b98-0563-43b0-9849-14bf4553f651, headers:{'Content-Type': 'application/json', 'accept': 'application/snowflake', 'User-Agent': 'PythonConnector/3.7.1 (Linux-6.6.16-linuxkit-aarch64-with-glibc2.36) CPython/3.12.2', 'Content-Encoding': 'gzip'}, data: {"data": {"CLIENT_APP_ID": "PythonConnector", "CLIENT_APP_VERSION": "3.7.1", "SVN_REVISION": null, "ACCOUNT_NAME": "jg26601", "LOGIN_NAME": "dandataldn", "CLIENT_ENVIRONMENT": {"APPLICATION": "AIRFLOW", "OS": "Linux", "OS_VERSION": "Linux-6.6.16-linuxkit-aarch64-with-glibc2.36", "PYTHON_VERSION": "3.12.2", "PYTHON_RUNTIME": "CPython", "PYTHON_COMPILER": "GCC 12.2.0", "OCSP_MODE": "FAIL_OPEN", "TRACING": 20, "LOGIN_TIMEOUT": null, "NETWORK_TIMEOUT": null, "SOCKET_TIMEOUT": null}, "PASSWORD": "**** "SESSION_PARAMETERS": {"CLIENT_PREFETCH_THREADS": 4}}}
[2024-04-22T15:01:33.940+0000] {connection.py:547} WARNING - Certificate did not match expected hostname: jg26601.eu-west-2.aws.snowflakecomputing.com.snowflakecomputing.com. Certificate: {'subject': ((('commonName', '*.prod3.us-west-2.snowflakecomputing.com'),),), 'subjectAltName': [('DNS', '*.prod3.us-west-2.snowflakecomputing.com'), ('DNS', '*.us-west-2.snowflakecomputing.com'), ('DNS', '*.global.snowflakecomputing.com'), ('DNS', '*.snowflakecomputing.com'), ('DNS', '*.prod3.us-west-2.aws.snowflakecomputing.com')]}
[2024-04-22T15:01:33.943+0000] {connectionpool.py:824} WARNING - Retrying (Retry(total=0, connect=None, read=None, redirect=None, status=None)) after connection broken by 'SSLError(CertificateError("hostname 'jg26601.eu-west-2.aws.snowflakecomputing.com.snowflakecomputing.com' doesn't match either of '*.prod3.us-west-2.snowflakecomputing.com', '*.us-west-2.snowflakecomputing.com', '*.global.snowflakecomputing.com', '*.snowflakecomputing.com', '*.prod3.us-west-2.aws.snowflakecomputing.com'"))': /session/v1/login-request?request_id=d8f81edc-fa70-4af3-afb1-25e791106561&databaseName=AMAZON&schemaName=RAW&warehouse=COMPUTE_WH&roleName=&request_guid=cc734104-da87-450f-b183-81a82f44ce1b
[2024-04-22T15:01:34.471+0000] {connection.py:547} WARNING - Certificate did not match expected hostname: jg26601.eu-west-2.aws.snowflakecomputing.com.snowflakecomputing.com. Certificate: {'subject': ((('commonName', '*.prod3.us-west-2.snowflakecomputing.com'),),), 'subjectAltName': [('DNS', '*.prod3.us-west-2.snowflakecomputing.com'), ('DNS', '*.us-west-2.snowflakecomputing.com'), ('DNS', '*.global.snowflakecomputing.com'), ('DNS', '*.snowflakecomputing.com'), ('DNS', '*.prod3.us-west-2.aws.snowflakecomputing.com')]}
[2024-04-22T15:01:34.481+0000] {network.py:1029} ERROR - Failed to get the response. Hanging? method: post, url: https://jg26601.eu-west-2.aws.snowflakecomputing.com.snowflakecomputing.com:443/session/v1/login-request?request_id=d8f81edc-fa70-4af3-afb1-25e791106561&databaseName=AMAZON&schemaName=RAW&warehouse=COMPUTE_WH&roleName=&request_guid=cc734104-da87-450f-b183-81a82f44ce1b, headers:{'Content-Type': 'application/json', 'accept': 'application/snowflake', 'User-Agent': 'PythonConnector/3.7.1 (Linux-6.6.16-linuxkit-aarch64-with-glibc2.36) CPython/3.12.2', 'Content-Encoding': 'gzip'}, data: {"data": {"CLIENT_APP_ID": "PythonConnector", "CLIENT_APP_VERSION": "3.7.1", "SVN_REVISION": null, "ACCOUNT_NAME": "jg26601", "LOGIN_NAME": "dandataldn", "CLIENT_ENVIRONMENT": {"APPLICATION": "AIRFLOW", "OS": "Linux", "OS_VERSION": "Linux-6.6.16-linuxkit-aarch64-with-glibc2.36", "PYTHON_VERSION": "3.12.2", "PYTHON_RUNTIME": "CPython", "PYTHON_COMPILER": "GCC 12.2.0", "OCSP_MODE": "FAIL_OPEN", "TRACING": 20, "LOGIN_TIMEOUT": null, "NETWORK_TIMEOUT": null, "SOCKET_TIMEOUT": null}, "PASSWORD": "**** "SESSION_PARAMETERS": {"CLIENT_PREFETCH_THREADS": 4}}}
[2024-04-22T15:01:34.488+0000] {taskinstance.py:441} INFO - ::group::Post task execution logs
[2024-04-22T15:01:34.490+0000] {taskinstance.py:2890} ERROR - Task failed with exception
Traceback (most recent call last):
  File "/home/airflow/.local/lib/python3.12/site-packages/snowflake/connector/connection.py", line 1345, in _authenticate
    auth.authenticate(
  File "/home/airflow/.local/lib/python3.12/site-packages/snowflake/connector/auth/_auth.py", line 250, in authenticate
    ret = self._rest._post_request(
          ^^^^^^^^^^^^^^^^^^^^^^^^^
  File "/home/airflow/.local/lib/python3.12/site-packages/snowflake/connector/network.py", line 734, in _post_request
    ret = self.fetch(
          ^^^^^^^^^^^
  File "/home/airflow/.local/lib/python3.12/site-packages/snowflake/connector/network.py", line 843, in fetch
    ret = self._request_exec_wrapper(
          ^^^^^^^^^^^^^^^^^^^^^^^^^^^
  File "/home/airflow/.local/lib/python3.12/site-packages/snowflake/connector/network.py", line 979, in _request_exec_wrapper
    raise e
  File "/home/airflow/.local/lib/python3.12/site-packages/snowflake/connector/network.py", line 895, in _request_exec_wrapper
    self._handle_unknown_error(method, full_url, headers, data, conn)
  File "/home/airflow/.local/lib/python3.12/site-packages/snowflake/connector/network.py", line 1034, in _handle_unknown_error
    Error.errorhandler_wrapper(
  File "/home/airflow/.local/lib/python3.12/site-packages/snowflake/connector/errors.py", line 290, in errorhandler_wrapper
    handed_over = Error.hand_to_other_handler(
                  ^^^^^^^^^^^^^^^^^^^^^^^^^^^^
  File "/home/airflow/.local/lib/python3.12/site-packages/snowflake/connector/errors.py", line 348, in hand_to_other_handler
    connection.errorhandler(connection, cursor, error_class, error_value)
  File "/home/airflow/.local/lib/python3.12/site-packages/snowflake/connector/errors.py", line 221, in default_errorhandler
    raise error_class(
snowflake.connector.errors.OperationalError: 250003: 250003: Failed to get the response. Hanging? method: post, url: https://jg26601.eu-west-2.aws.snowflakecomputing.com.snowflakecomputing.com:443/session/v1/login-request?request_id=e1048fbe-72c8-43ac-a6ee-add1f9b708ec&databaseName=AMAZON&schemaName=RAW&warehouse=COMPUTE_WH&roleName=&request_guid=91004b98-0563-43b0-9849-14bf4553f651

The above exception was the direct cause of the following exception:

Traceback (most recent call last):
  File "/home/airflow/.local/lib/python3.12/site-packages/airflow/models/taskinstance.py", line 465, in _execute_task
    result = _execute_callable(context=context, **execute_callable_kwargs)
             ^^^^^^^^^^^^^^^^^^^^^^^^^^^^^^^^^^^^^^^^^^^^^^^^^^^^^^^^^^^^^
  File "/home/airflow/.local/lib/python3.12/site-packages/airflow/models/taskinstance.py", line 432, in _execute_callable
    return execute_callable(context=context, **execute_callable_kwargs)
           ^^^^^^^^^^^^^^^^^^^^^^^^^^^^^^^^^^^^^^^^^^^^^^^^^^^^^^^^^^^^
  File "/home/airflow/.local/lib/python3.12/site-packages/airflow/models/baseoperator.py", line 400, in wrapper
    return func(self, *args, **kwargs)
           ^^^^^^^^^^^^^^^^^^^^^^^^^^^
  File "/home/airflow/.local/lib/python3.12/site-packages/airflow/providers/common/sql/operators/sql.py", line 282, in execute
    output = hook.run(
             ^^^^^^^^^
  File "/home/airflow/.local/lib/python3.12/site-packages/airflow/providers/snowflake/hooks/snowflake.py", line 384, in run
    with closing(self.get_conn()) as conn:
                 ^^^^^^^^^^^^^^^
  File "/home/airflow/.local/lib/python3.12/site-packages/airflow/providers/snowflake/hooks/snowflake.py", line 278, in get_conn
    conn = connector.connect(**conn_config)
           ^^^^^^^^^^^^^^^^^^^^^^^^^^^^^^^^
  File "/home/airflow/.local/lib/python3.12/site-packages/snowflake/connector/__init__.py", line 54, in Connect
    return SnowflakeConnection(**kwargs)
           ^^^^^^^^^^^^^^^^^^^^^^^^^^^^^
  File "/home/airflow/.local/lib/python3.12/site-packages/snowflake/connector/connection.py", line 429, in __init__
    self.connect(**kwargs)
  File "/home/airflow/.local/lib/python3.12/site-packages/snowflake/connector/connection.py", line 719, in connect
    self.__open_connection()
  File "/home/airflow/.local/lib/python3.12/site-packages/snowflake/connector/connection.py", line 1045, in __open_connection
    self.authenticate_with_retry(self.auth_class)
  File "/home/airflow/.local/lib/python3.12/site-packages/snowflake/connector/connection.py", line 1317, in authenticate_with_retry
    self._authenticate(auth_instance)
  File "/home/airflow/.local/lib/python3.12/site-packages/snowflake/connector/connection.py", line 1389, in _authenticate
    raise auth_op from e
  File "/home/airflow/.local/lib/python3.12/site-packages/snowflake/connector/connection.py", line 1366, in _authenticate
    auth_instance.handle_timeout(
  File "/home/airflow/.local/lib/python3.12/site-packages/snowflake/connector/auth/by_plugin.py", line 212, in handle_timeout
    raise error
snowflake.connector.errors.OperationalError: 250001: 250001: Could not connect to Snowflake backend after 2 attempt(s).Aborting
[2024-04-22T15:01:34.511+0000] {taskinstance.py:1205} INFO - Marking task as FAILED. dag_id=amazon_test, task_id=snowflake_op_sql_str, execution_date=20240301T000000, start_date=20240422T150131, end_date=20240422T150134
[2024-04-22T15:01:34.525+0000] {standard_task_runner.py:110} ERROR - Failed to execute job 5 for task snowflake_op_sql_str (250001: 250001: Could not connect to Snowflake backend after 2 attempt(s).Aborting; 378)
[2024-04-22T15:01:34.565+0000] {local_task_job_runner.py:240} INFO - Task exited with return code 1
[2024-04-22T15:01:34.582+0000] {warnings.py:110} WARNING - /home/***/.local/lib/python3.12/site-packages/***/models/baseoperator.py:1296: AirflowProviderDeprecationWarning: Call to deprecated class SnowflakeOperator. (This class is deprecated. Please use `***.providers.common.sql.operators.sql.SQLExecuteQueryOperator`. Also, you can provide `hook_params={'warehouse': <warehouse>, 'database': <database>, 'role': <role>, 'schema': <schema>, 'authenticator': <authenticator>,'session_parameters': <session_parameters>}`.)
  result = cls.__new__(cls)

[2024-04-22T15:01:34.590+0000] {taskinstance.py:3482} INFO - 0 downstream tasks scheduled from follow-on schedule check
[2024-04-22T15:01:34.594+0000] {local_task_job_runner.py:222} INFO - ::endgroup::
